<?xml version="1.0"?>
<robot name="humanoid_with_description" xmlns:xacro="http://www.ros.org/wiki/xacro">
  <!-- This URDF includes more detailed descriptions for textbook purposes -->

  <!-- Base/World link -->
  <link name="world"/>

  <!-- Floating base joint -->
  <joint name="world_to_base" type="floating">
    <parent link="world"/>
    <child link="base_link"/>
    <origin xyz="0 0 0.8" rpy="0 0 0"/>
  </joint>

  <!-- Main body (pelvis) -->
  <link name="base_link">
    <visual>
      <origin xyz="0 0 0" rpy="0 0 0"/>
      <geometry>
        <box size="0.2 0.25 0.15"/>
      </geometry>
      <material name="light_gray">
        <color rgba="0.7 0.7 0.7 1"/>
      </material>
    </visual>
    <collision>
      <origin xyz="0 0 0" rpy="0 0 0"/>
      <geometry>
        <box size="0.2 0.25 0.15"/>
      </geometry>
    </collision>
    <inertial>
      <mass value="10.0"/>
      <inertia ixx="0.2" ixy="0.0" ixz="0.0" iyy="0.15" iyz="0.0" izz="0.1"/>
    </inertial>
  </link>

  <!-- Torso -->
  <link name="torso">
    <visual>
      <origin xyz="0 0 0.25" rpy="0 0 0"/>
      <geometry>
        <box size="0.18 0.2 0.5"/>
      </geometry>
      <material name="blue">
        <color rgba="0.2 0.2 1.0 1"/>
      </material>
    </visual>
    <collision>
      <origin xyz="0 0 0.25" rpy="0 0 0"/>
      <geometry>
        <box size="0.18 0.2 0.5"/>
      </geometry>
    </collision>
    <inertial>
      <mass value="8.0"/>
      <inertia ixx="0.4" ixy="0.0" ixz="0.0" iyy="0.35" iyz="0.0" izz="0.2"/>
    </inertial>
  </link>

  <joint name="torso_joint" type="fixed">
    <parent link="base_link"/>
    <child link="torso"/>
    <origin xyz="0 0 0.075"/>
  </joint>

  <!-- Head -->
  <link name="head">
    <visual>
      <origin xyz="0 0 0.1" rpy="0 0 0"/>
      <geometry>
        <sphere radius="0.1"/>
      </geometry>
      <material name="skin">
        <color rgba="0.8 0.6 0.4 1"/>
      </material>
    </visual>
    <collision>
      <origin xyz="0 0 0.1" rpy="0 0 0"/>
      <geometry>
        <sphere radius="0.1"/>
      </geometry>
    </collision>
    <inertial>
      <mass value="2.0"/>
      <inertia ixx="0.02" ixy="0.0" ixz="0.0" iyy="0.02" iyz="0.0" izz="0.02"/>
    </inertial>
  </link>

  <joint name="neck_joint" type="revolute">
    <parent link="torso"/>
    <child link="head"/>
    <origin xyz="0 0 0.5"/>
    <axis xyz="0 1 0"/>
    <limit lower="-0.5" upper="0.5" effort="10" velocity="2"/>
  </joint>

  <!-- Left Arm -->
  <link name="left_shoulder">
    <visual>
      <origin xyz="0 0 0" rpy="0 0 0"/>
      <geometry>
        <cylinder length="0.1" radius="0.06"/>
      </geometry>
      <material name="red">
        <color rgba="1.0 0.2 0.2 1"/>
      </material>
    </visual>
    <collision>
      <origin xyz="0 0 0" rpy="0 0 0"/>
      <geometry>
        <cylinder length="0.1" radius="0.06"/>
      </geometry>
    </collision>
    <inertial>
      <mass value="1.0"/>
      <inertia ixx="0.005" ixy="0.0" ixz="0.0" iyy="0.005" iyz="0.0" izz="0.005"/>
    </inertial>
  </link>

  <joint name="left_shoulder_joint" type="revolute">
    <parent link="torso"/>
    <child link="left_shoulder"/>
    <origin xyz="0.1 0 0.35"/>
    <axis xyz="0 1 0"/>
    <limit lower="-1.57" upper="1.57" effort="50" velocity="2"/>
  </joint>

  <link name="left_upper_arm">
    <visual>
      <origin xyz="0 0 -0.15" rpy="0 0 0"/>
      <geometry>
        <cylinder length="0.3" radius="0.05"/>
      </geometry>
      <material name="red">
        <color rgba="1.0 0.2 0.2 1"/>
      </material>
    </visual>
    <collision>
      <origin xyz="0 0 -0.15" rpy="0 0 0"/>
      <geometry>
        <cylinder length="0.3" radius="0.05"/>
      </geometry>
    </collision>
    <inertial>
      <mass value="1.5"/>
      <inertia ixx="0.01" ixy="0.0" ixz="0.0" iyy="0.01" iyz="0.0" izz="0.005"/>
    </inertial>
  </link>

  <joint name="left_elbow_joint" type="revolute">
    <parent link="left_shoulder"/>
    <child link="left_upper_arm"/>
    <origin xyz="0 0 -0.1"/>
    <axis xyz="1 0 0"/>
    <limit lower="-1.57" upper="1.57" effort="50" velocity="2"/>
  </joint>

  <link name="left_lower_arm">
    <visual>
      <origin xyz="0 0 -0.12" rpy="0 0 0"/>
      <geometry>
        <cylinder length="0.24" radius="0.04"/>
      </geometry>
      <material name="red">
        <color rgba="1.0 0.2 0.2 1"/>
      </material>
    </visual>
    <collision>
      <origin xyz="0 0 -0.12" rpy="0 0 0"/>
      <geometry>
        <cylinder length="0.24" radius="0.04"/>
      </geometry>
    </collision>
    <inertial>
      <mass value="1.0"/>
      <inertia ixx="0.006" ixy="0.0" ixz="0.0" iyy="0.006" iyz="0.0" izz="0.003"/>
    </inertial>
  </link>

  <joint name="left_wrist_joint" type="revolute">
    <parent link="left_upper_arm"/>
    <child link="left_lower_arm"/>
    <origin xyz="0 0 -0.3"/>
    <axis xyz="1 0 0"/>
    <limit lower="-1.57" upper="1.57" effort="30" velocity="2"/>
  </joint>

  <link name="left_hand">
    <visual>
      <origin xyz="0 0 -0.05" rpy="0 0 0"/>
      <geometry>
        <box size="0.12 0.08 0.1"/>
      </geometry>
      <material name="red">
        <color rgba="1.0 0.2 0.2 1"/>
      </material>
    </visual>
    <collision>
      <origin xyz="0 0 -0.05" rpy="0 0 0"/>
      <geometry>
        <box size="0.12 0.08 0.1"/>
      </geometry>
    </collision>
    <inertial>
      <mass value="0.5"/>
      <inertia ixx="0.001" ixy="0.0" ixz="0.0" iyy="0.001" iyz="0.0" izz="0.001"/>
    </inertial>
  </link>

  <joint name="left_hand_joint" type="fixed">
    <parent link="left_lower_arm"/>
    <child link="left_hand"/>
    <origin xyz="0 0 -0.12"/>
  </joint>

  <!-- Right Arm -->
  <link name="right_shoulder">
    <visual>
      <origin xyz="0 0 0" rpy="0 0 0"/>
      <geometry>
        <cylinder length="0.1" radius="0.06"/>
      </geometry>
      <material name="red">
        <color rgba="1.0 0.2 0.2 1"/>
      </material>
    </visual>
    <collision>
      <origin xyz="0 0 0" rpy="0 0 0"/>
      <geometry>
        <cylinder length="0.1" radius="0.06"/>
      </geometry>
    </collision>
    <inertial>
      <mass value="1.0"/>
      <inertia ixx="0.005" ixy="0.0" ixz="0.0" iyy="0.005" iyz="0.0" izz="0.005"/>
    </inertial>
  </link>

  <joint name="right_shoulder_joint" type="revolute">
    <parent link="torso"/>
    <child link="right_shoulder"/>
    <origin xyz="-0.1 0 0.35"/>
    <axis xyz="0 1 0"/>
    <limit lower="-1.57" upper="1.57" effort="50" velocity="2"/>
  </joint>

  <link name="right_upper_arm">
    <visual>
      <origin xyz="0 0 -0.15" rpy="0 0 0"/>
      <geometry>
        <cylinder length="0.3" radius="0.05"/>
      </geometry>
      <material name="red">
        <color rgba="1.0 0.2 0.2 1"/>
      </material>
    </visual>
    <collision>
      <origin xyz="0 0 -0.15" rpy="0 0 0"/>
      <geometry>
        <cylinder length="0.3" radius="0.05"/>
      </geometry>
    </collision>
    <inertial>
      <mass value="1.5"/>
      <inertia ixx="0.01" ixy="0.0" ixz="0.0" iyy="0.01" iyz="0.0" izz="0.005"/>
    </inertial>
  </link>

  <joint name="right_elbow_joint" type="revolute">
    <parent link="right_shoulder"/>
    <child link="right_upper_arm"/>
    <origin xyz="0 0 -0.1"/>
    <axis xyz="1 0 0"/>
    <limit lower="-1.57" upper="1.57" effort="50" velocity="2"/>
  </joint>

  <link name="right_lower_arm">
    <visual>
      <origin xyz="0 0 -0.12" rpy="0 0 0"/>
      <geometry>
        <cylinder length="0.24" radius="0.04"/>
      </geometry>
      <material name="red">
        <color rgba="1.0 0.2 0.2 1"/>
      </material>
    </visual>
    <collision>
      <origin xyz="0 0 -0.12" rpy="0 0 0"/>
      <geometry>
        <cylinder length="0.24" radius="0.04"/>
      </geometry>
    </collision>
    <inertial>
      <mass value="1.0"/>
      <inertia ixx="0.006" ixy="0.0" ixz="0.0" iyy="0.006" iyz="0.0" izz="0.003"/>
    </inertial>
  </link>

  <joint name="right_wrist_joint" type="revolute">
    <parent link="right_upper_arm"/>
    <child link="right_lower_arm"/>
    <origin xyz="0 0 -0.3"/>
    <axis xyz="1 0 0"/>
    <limit lower="-1.57" upper="1.57" effort="30" velocity="2"/>
  </joint>

  <link name="right_hand">
    <visual>
      <origin xyz="0 0 -0.05" rpy="0 0 0"/>
      <geometry>
        <box size="0.12 0.08 0.1"/>
      </geometry>
      <material name="red">
        <color rgba="1.0 0.2 0.2 1"/>
      </material>
    </visual>
    <collision>
      <origin xyz="0 0 -0.05" rpy="0 0 0"/>
      <geometry>
        <box size="0.12 0.08 0.1"/>
      </geometry>
    </collision>
    <inertial>
      <mass value="0.5"/>
      <inertia ixx="0.001" ixy="0.0" ixz="0.0" iyy="0.001" iyz="0.0" izz="0.001"/>
    </inertial>
  </link>

  <joint name="right_hand_joint" type="fixed">
    <parent link="right_lower_arm"/>
    <child link="right_hand"/>
    <origin xyz="0 0 -0.12"/>
  </joint>

  <!-- Left Leg -->
  <link name="left_pelvis">
    <visual>
      <origin xyz="0 0 0" rpy="0 0 0"/>
      <geometry>
        <cylinder length="0.1" radius="0.07"/>
      </geometry>
      <material name="green">
        <color rgba="0.2 1.0 0.2 1"/>
      </material>
    </visual>
    <collision>
      <origin xyz="0 0 0" rpy="0 0 0"/>
      <geometry>
        <cylinder length="0.1" radius="0.07"/>
      </geometry>
    </collision>
    <inertial>
      <mass value="1.5"/>
      <inertia ixx="0.006" ixy="0.0" ixz="0.0" iyy="0.006" iyz="0.0" izz="0.006"/>
    </inertial>
  </link>

  <joint name="left_hip_joint" type="revolute">
    <parent link="base_link"/>
    <child link="left_pelvis"/>
    <origin xyz="0.07 0 -0.075"/>
    <axis xyz="0 1 0"/>
    <limit lower="-0.5" upper="0.5" effort="100" velocity="2"/>
  </joint>

  <link name="left_thigh">
    <visual>
      <origin xyz="0 0 -0.2" rpy="0 0 0"/>
      <geometry>
        <cylinder length="0.4" radius="0.06"/>
      </geometry>
      <material name="green">
        <color rgba="0.2 1.0 0.2 1"/>
      </material>
    </visual>
    <collision>
      <origin xyz="0 0 -0.2" rpy="0 0 0"/>
      <geometry>
        <cylinder length="0.4" radius="0.06"/>
      </geometry>
    </collision>
    <inertial>
      <mass value="3.0"/>
      <inertia ixx="0.04" ixy="0.0" ixz="0.0" iyy="0.04" iyz="0.0" izz="0.01"/>
    </inertial>
  </link>

  <joint name="left_knee_joint" type="revolute">
    <parent link="left_pelvis"/>
    <child link="left_thigh"/>
    <origin xyz="0 0 -0.1"/>
    <axis xyz="1 0 0"/>
    <limit lower="0" upper="1.57" effort="100" velocity="2"/>
  </joint>

  <link name="left_shin">
    <visual>
      <origin xyz="0 0 -0.18" rpy="0 0 0"/>
      <geometry>
        <cylinder length="0.36" radius="0.05"/>
      </geometry>
      <material name="green">
        <color rgba="0.2 1.0 0.2 1"/>
      </material>
    </visual>
    <collision>
      <origin xyz="0 0 -0.18" rpy="0 0 0"/>
      <geometry>
        <cylinder length="0.36" radius="0.05"/>
      </geometry>
    </collision>
    <inertial>
      <mass value="2.0"/>
      <inertia ixx="0.025" ixy="0.0" ixz="0.0" iyy="0.025" iyz="0.0" izz="0.008"/>
    </inertial>
  </link>

  <joint name="left_ankle_joint" type="revolute">
    <parent link="left_thigh"/>
    <child link="left_shin"/>
    <origin xyz="0 0 -0.4"/>
    <axis xyz="1 0 0"/>
    <limit lower="-0.5" upper="0.5" effort="50" velocity="2"/>
  </joint>

  <link name="left_foot">
    <visual>
      <origin xyz="0 0 -0.03" rpy="0 0 0"/>
      <geometry>
        <box size="0.18 0.08 0.06"/>
      </geometry>
      <material name="green">
        <color rgba="0.2 1.0 0.2 1"/>
      </material>
    </visual>
    <collision>
      <origin xyz="0 0 -0.03" rpy="0 0 0"/>
      <geometry>
        <box size="0.18 0.08 0.06"/>
      </geometry>
    </collision>
    <inertial>
      <mass value="1.0"/>
      <inertia ixx="0.002" ixy="0.0" ixz="0.0" iyy="0.002" iyz="0.0" izz="0.002"/>
    </inertial>
  </link>

  <joint name="left_foot_joint" type="fixed">
    <parent link="left_shin"/>
    <child link="left_foot"/>
    <origin xyz="0 0 -0.2"/>
  </joint>

  <!-- Right Leg -->
  <link name="right_pelvis">
    <visual>
      <origin xyz="0 0 0" rpy="0 0 0"/>
      <geometry>
        <cylinder length="0.1" radius="0.07"/>
      </geometry>
      <material name="green">
        <color rgba="0.2 1.0 0.2 1"/>
      </material>
    </visual>
    <collision>
      <origin xyz="0 0 0" rpy="0 0 0"/>
      <geometry>
        <cylinder length="0.1" radius="0.07"/>
      </geometry>
    </collision>
    <inertial>
      <mass value="1.5"/>
      <inertia ixx="0.006" ixy="0.0" ixz="0.0" iyy="0.006" iyz="0.0" izz="0.006"/>
    </inertial>
  </link>

  <joint name="right_hip_joint" type="revolute">
    <parent link="base_link"/>
    <child link="right_pelvis"/>
    <origin xyz="-0.07 0 -0.075"/>
    <axis xyz="0 1 0"/>
    <limit lower="-0.5" upper="0.5" effort="100" velocity="2"/>
  </joint>

  <link name="right_thigh">
    <visual>
      <origin xyz="0 0 -0.2" rpy="0 0 0"/>
      <geometry>
        <cylinder length="0.4" radius="0.06"/>
      </geometry>
      <material name="green">
        <color rgba="0.2 1.0 0.2 1"/>
      </material>
    </visual>
    <collision>
      <origin xyz="0 0 -0.2" rpy="0 0 0"/>
      <geometry>
        <cylinder length="0.4" radius="0.06"/>
      </geometry>
    </collision>
    <inertial>
      <mass value="3.0"/>
      <inertia ixx="0.04" ixy="0.0" ixz="0.0" iyy="0.04" iyz="0.0" izz="0.01"/>
    </inertial>
  </link>

  <joint name="right_knee_joint" type="revolute">
    <parent link="right_pelvis"/>
    <child link="right_thigh"/>
    <origin xyz="0 0 -0.1"/>
    <axis xyz="1 0 0"/>
    <limit lower="0" upper="1.57" effort="100" velocity="2"/>
  </joint>

  <link name="right_shin">
    <visual>
      <origin xyz="0 0 -0.18" rpy="0 0 0"/>
      <geometry>
        <cylinder length="0.36" radius="0.05"/>
      </geometry>
      <material name="green">
        <color rgba="0.2 1.0 0.2 1"/>
      </material>
    </visual>
    <collision>
      <origin xyz="0 0 -0.18" rpy="0 0 0"/>
      <geometry>
        <cylinder length="0.36" radius="0.05"/>
      </geometry>
    </collision>
    <inertial>
      <mass value="2.0"/>
      <inertia ixx="0.025" ixy="0.0" ixz="0.0" iyy="0.025" iyz="0.0" izz="0.008"/>
    </inertial>
  </link>

  <joint name="right_ankle_joint" type="revolute">
    <parent link="right_thigh"/>
    <child link="right_shin"/>
    <origin xyz="0 0 -0.4"/>
    <axis xyz="1 0 0"/>
    <limit lower="-0.5" upper="0.5" effort="50" velocity="2"/>
  </joint>

  <link name="right_foot">
    <visual>
      <origin xyz="0 0 -0.03" rpy="0 0 0"/>
      <geometry>
        <box size="0.18 0.08 0.06"/>
      </geometry>
      <material name="green">
        <color rgba="0.2 1.0 0.2 1"/>
      </material>
    </visual>
    <collision>
      <origin xyz="0 0 -0.03" rpy="0 0 0"/>
      <geometry>
        <box size="0.18 0.08 0.06"/>
      </geometry>
    </collision>
    <inertial>
      <mass value="1.0"/>
      <inertia ixx="0.002" ixy="0.0" ixz="0.0" iyy="0.002" iyz="0.0" izz="0.002"/>
    </inertial>
  </link>

  <joint name="right_foot_joint" type="fixed">
    <parent link="right_shin"/>
    <child link="right_foot"/>
    <origin xyz="0 0 -0.2"/>
  </joint>
</robot>