<?xml version="1.0"?>
<robot name="simulation_humanoid" xmlns:xacro="http://www.ros.org/wiki/xacro">

  <!-- Gazebo plugin for ROS control -->
  <gazebo>
    <plugin name="gazebo_ros_control" filename="libgazebo_ros_control.so">
      <robotNamespace>/simulation_humanoid</robotNamespace>
      <controlPeriod>0.001</controlPeriod>
      <legacyModeNS>true</legacyModeNS>
    </plugin>
  </gazebo>

  <!-- Materials -->
  <material name="blue">
    <color rgba="0.0 0.0 1.0 1.0"/>
  </material>
  <material name="red">
    <color rgba="1.0 0.0 0.0 1.0"/>
  </material>
  <material name="green">
    <color rgba="0.0 1.0 0.0 1.0"/>
  </material>
  <material name="yellow">
    <color rgba="1.0 1.0 0.0 1.0"/>
  </material>
  <material name="black">
    <color rgba="0.0 0.0 0.0 1.0"/>
  </material>
  <material name="white">
    <color rgba="1.0 1.0 1.0 1.0"/>
  </material>

  <!-- Base link -->
  <link name="base_link">
    <inertial>
      <mass value="10.0"/>
      <origin xyz="0 0 0"/>
      <inertia ixx="0.1" ixy="0.0" ixz="0.0" iyy="0.1" iyz="0.0" izz="0.1"/>
    </inertial>
    <visual>
      <origin xyz="0 0 0"/>
      <geometry>
        <box size="0.1 0.1 0.1"/>
      </geometry>
      <material name="blue"/>
    </visual>
    <collision>
      <origin xyz="0 0 0"/>
      <geometry>
        <box size="0.1 0.1 0.1"/>
      </geometry>
    </collision>
  </link>

  <!-- Pelvis -->
  <link name="pelvis">
    <inertial>
      <mass value="5.0"/>
      <origin xyz="0 0 0"/>
      <inertia ixx="0.08" ixy="0.0" ixz="0.0" iyy="0.08" iyz="0.0" izz="0.08"/>
    </inertial>
    <visual>
      <origin xyz="0 0 0"/>
      <geometry>
        <box size="0.25 0.15 0.1"/>
      </geometry>
      <material name="red"/>
    </visual>
    <collision>
      <origin xyz="0 0 0"/>
      <geometry>
        <box size="0.25 0.15 0.1"/>
      </geometry>
    </collision>
  </link>

  <joint name="base_to_pelvis" type="fixed">
    <parent link="base_link"/>
    <child link="pelvis"/>
    <origin xyz="0 0 0.1"/>
  </joint>

  <!-- Torso -->
  <link name="torso">
    <inertial>
      <mass value="6.0"/>
      <origin xyz="0 0 0.15"/>
      <inertia ixx="0.12" ixy="0.0" ixz="0.0" iyy="0.12" iyz="0.0" izz="0.08"/>
    </inertial>
    <visual>
      <origin xyz="0 0 0.15"/>
      <geometry>
        <box size="0.2 0.15 0.3"/>
      </geometry>
      <material name="red"/>
    </visual>
    <collision>
      <origin xyz="0 0 0.15"/>
      <geometry>
        <box size="0.2 0.15 0.3"/>
      </geometry>
    </collision>
  </link>

  <joint name="pelvis_to_torso" type="fixed">
    <parent link="pelvis"/>
    <child link="torso"/>
    <origin xyz="0 0 0.15"/>
  </joint>

  <!-- Head -->
  <link name="head">
    <inertial>
      <mass value="2.0"/>
      <origin xyz="0 0 0.05"/>
      <inertia ixx="0.008" ixy="0.0" ixz="0.0" iyy="0.008" iyz="0.0" izz="0.008"/>
    </inertial>
    <visual>
      <origin xyz="0 0 0.05"/>
      <geometry>
        <sphere radius="0.1"/>
      </geometry>
      <material name="white"/>
    </visual>
    <collision>
      <origin xyz="0 0 0.05"/>
      <geometry>
        <sphere radius="0.1"/>
      </geometry>
    </collision>
  </link>

  <joint name="torso_to_head" type="fixed">
    <parent link="torso"/>
    <child link="head"/>
    <origin xyz="0 0 0.35"/>
  </joint>

  <!-- Left Hip (3 DOF) -->
  <link name="left_hip_roll">
    <inertial>
      <mass value="1.0"/>
      <origin xyz="0 0 -0.05"/>
      <inertia ixx="0.002" ixy="0.0" ixz="0.0" iyy="0.002" iyz="0.0" izz="0.001"/>
    </inertial>
    <visual>
      <origin xyz="0 0 -0.05"/>
      <geometry>
        <cylinder length="0.1" radius="0.04"/>
      </geometry>
      <material name="green"/>
      <origin rpy="1.57075 0 0"/>
    </visual>
    <collision>
      <origin xyz="0 0 -0.05"/>
      <geometry>
        <cylinder length="0.1" radius="0.04"/>
      </geometry>
      <origin rpy="1.57075 0 0"/>
    </collision>
  </link>

  <joint name="left_hip_roll_joint" type="revolute">
    <parent link="pelvis"/>
    <child link="left_hip_roll"/>
    <origin xyz="-0.08 0 0"/>
    <axis xyz="1 0 0"/>
    <limit lower="-0.5" upper="0.5" effort="200" velocity="2"/>
    <dynamics damping="1.0" friction="0.1"/>
  </joint>

  <link name="left_hip_yaw">
    <inertial>
      <mass value="1.0"/>
      <origin xyz="0 0 -0.05"/>
      <inertia ixx="0.002" ixy="0.0" ixz="0.0" iyy="0.002" iyz="0.0" izz="0.001"/>
    </inertial>
    <visual>
      <origin xyz="0 0 -0.05"/>
      <geometry>
        <cylinder length="0.1" radius="0.04"/>
      </geometry>
      <material name="green"/>
      <origin rpy="1.57075 0 0"/>
    </visual>
    <collision>
      <origin xyz="0 0 -0.05"/>
      <geometry>
        <cylinder length="0.1" radius="0.04"/>
      </geometry>
      <origin rpy="1.57075 0 0"/>
    </collision>
  </link>

  <joint name="left_hip_yaw_joint" type="revolute">
    <parent link="left_hip_roll"/>
    <child link="left_hip_yaw"/>
    <origin xyz="0 0 -0.05"/>
    <axis xyz="0 0 1"/>
    <limit lower="-0.5" upper="0.5" effort="200" velocity="2"/>
    <dynamics damping="1.0" friction="0.1"/>
  </joint>

  <link name="left_hip_pitch">
    <inertial>
      <mass value="1.0"/>
      <origin xyz="0 0 -0.1"/>
      <inertia ixx="0.003" ixy="0.0" ixz="0.0" iyy="0.003" iyz="0.0" izz="0.001"/>
    </inertial>
    <visual>
      <origin xyz="0 0 -0.1"/>
      <geometry>
        <cylinder length="0.2" radius="0.04"/>
      </geometry>
      <material name="green"/>
      <origin rpy="1.57075 0 0"/>
    </visual>
    <collision>
      <origin xyz="0 0 -0.1"/>
      <geometry>
        <cylinder length="0.2" radius="0.04"/>
      </geometry>
      <origin rpy="1.57075 0 0"/>
    </collision>
  </link>

  <joint name="left_hip_pitch_joint" type="revolute">
    <parent link="left_hip_yaw"/>
    <child link="left_hip_pitch"/>
    <origin xyz="0 0 -0.05"/>
    <axis xyz="0 1 0"/>
    <limit lower="-1.57" upper="0.3" effort="300" velocity="2"/>
    <dynamics damping="1.0" friction="0.1"/>
  </joint>

  <!-- Left Thigh -->
  <link name="left_thigh">
    <inertial>
      <mass value="2.0"/>
      <origin xyz="0 0 -0.2"/>
      <inertia ixx="0.04" ixy="0.0" ixz="0.0" iyy="0.04" iyz="0.0" izz="0.01"/>
    </inertial>
    <visual>
      <origin xyz="0 0 -0.2"/>
      <geometry>
        <cylinder length="0.4" radius="0.05"/>
      </geometry>
      <material name="green"/>
      <origin rpy="1.57075 0 0"/>
    </visual>
    <collision>
      <origin xyz="0 0 -0.2"/>
      <geometry>
        <cylinder length="0.4" radius="0.05"/>
      </geometry>
      <origin rpy="1.57075 0 0"/>
    </collision>
  </link>

  <joint name="left_thigh_joint" type="revolute">
    <parent link="left_hip_pitch"/>
    <child link="left_thigh"/>
    <origin xyz="0 0 -0.1"/>
    <axis xyz="0 1 0"/>
    <limit lower="-0.2" upper="2.0" effort="300" velocity="2"/>
    <dynamics damping="1.0" friction="0.1"/>
  </joint>

  <!-- Left Shin -->
  <link name="left_shin">
    <inertial>
      <mass value="1.5"/>
      <origin xyz="0 0 -0.2"/>
      <inertia ixx="0.03" ixy="0.0" ixz="0.0" iyy="0.03" iyz="0.0" izz="0.008"/>
    </inertial>
    <visual>
      <origin xyz="0 0 -0.2"/>
      <geometry>
        <cylinder length="0.4" radius="0.04"/>
      </geometry>
      <material name="green"/>
      <origin rpy="1.57075 0 0"/>
    </visual>
    <collision>
      <origin xyz="0 0 -0.2"/>
      <geometry>
        <cylinder length="0.4" radius="0.04"/>
      </geometry>
      <origin rpy="1.57075 0 0"/>
    </collision>
  </link>

  <joint name="left_shin_joint" type="revolute">
    <parent link="left_thigh"/>
    <child link="left_shin"/>
    <origin xyz="0 0 -0.4"/>
    <axis xyz="0 1 0"/>
    <limit lower="-2.0" upper="0.5" effort="250" velocity="2"/>
    <dynamics damping="1.0" friction="0.1"/>
  </joint>

  <!-- Left Ankle -->
  <link name="left_ankle">
    <inertial>
      <mass value="0.8"/>
      <origin xyz="0 0 -0.03"/>
      <inertia ixx="0.001" ixy="0.0" ixz="0.0" iyy="0.001" iyz="0.0" izz="0.001"/>
    </inertial>
    <visual>
      <origin xyz="0 0 -0.03"/>
      <geometry>
        <box size="0.08 0.1 0.06"/>
      </geometry>
      <material name="black"/>
    </visual>
    <collision>
      <origin xyz="0 0 -0.03"/>
      <geometry>
        <box size="0.08 0.1 0.06"/>
      </geometry>
    </collision>
  </link>

  <joint name="left_ankle_joint" type="revolute">
    <parent link="left_shin"/>
    <child link="left_ankle"/>
    <origin xyz="0 0 -0.4"/>
    <axis xyz="0 1 0"/>
    <limit lower="-0.5" upper="0.5" effort="100" velocity="2"/>
    <dynamics damping="0.5" friction="0.1"/>
  </joint>

  <!-- Left Foot -->
  <link name="left_foot">
    <inertial>
      <mass value="0.8"/>
      <origin xyz="0.05 0 -0.05"/>
      <inertia ixx="0.002" ixy="0.0" ixz="0.0" iyy="0.003" iyz="0.0" izz="0.004"/>
    </inertial>
    <visual>
      <origin xyz="0.05 0 -0.05"/>
      <geometry>
        <box size="0.2 0.1 0.1"/>
      </geometry>
      <material name="black"/>
    </visual>
    <collision>
      <origin xyz="0.05 0 -0.05"/>
      <geometry>
        <box size="0.2 0.1 0.1"/>
      </geometry>
    </collision>
  </link>

  <joint name="left_foot_joint" type="fixed">
    <parent link="left_ankle"/>
    <child link="left_foot"/>
    <origin xyz="0.05 0 -0.08"/>
  </joint>

  <!-- Right Hip (3 DOF) -->
  <link name="right_hip_roll">
    <inertial>
      <mass value="1.0"/>
      <origin xyz="0 0 -0.05"/>
      <inertia ixx="0.002" ixy="0.0" ixz="0.0" iyy="0.002" iyz="0.0" izz="0.001"/>
    </inertial>
    <visual>
      <origin xyz="0 0 -0.05"/>
      <geometry>
        <cylinder length="0.1" radius="0.04"/>
      </geometry>
      <material name="green"/>
      <origin rpy="1.57075 0 0"/>
    </visual>
    <collision>
      <origin xyz="0 0 -0.05"/>
      <geometry>
        <cylinder length="0.1" radius="0.04"/>
      </geometry>
      <origin rpy="1.57075 0 0"/>
    </collision>
  </link>

  <joint name="right_hip_roll_joint" type="revolute">
    <parent link="pelvis"/>
    <child link="right_hip_roll"/>
    <origin xyz="0.08 0 0"/>
    <axis xyz="1 0 0"/>
    <limit lower="-0.5" upper="0.5" effort="200" velocity="2"/>
    <dynamics damping="1.0" friction="0.1"/>
  </joint>

  <link name="right_hip_yaw">
    <inertial>
      <mass value="1.0"/>
      <origin xyz="0 0 -0.05"/>
      <inertia ixx="0.002" ixy="0.0" ixz="0.0" iyy="0.002" iyz="0.0" izz="0.001"/>
    </inertial>
    <visual>
      <origin xyz="0 0 -0.05"/>
      <geometry>
        <cylinder length="0.1" radius="0.04"/>
      </geometry>
      <material name="green"/>
      <origin rpy="1.57075 0 0"/>
    </visual>
    <collision>
      <origin xyz="0 0 -0.05"/>
      <geometry>
        <cylinder length="0.1" radius="0.04"/>
      </geometry>
      <origin rpy="1.57075 0 0"/>
    </collision>
  </link>

  <joint name="right_hip_yaw_joint" type="revolute">
    <parent link="right_hip_roll"/>
    <child link="right_hip_yaw"/>
    <origin xyz="0 0 -0.05"/>
    <axis xyz="0 0 1"/>
    <limit lower="-0.5" upper="0.5" effort="200" velocity="2"/>
    <dynamics damping="1.0" friction="0.1"/>
  </joint>

  <link name="right_hip_pitch">
    <inertial>
      <mass value="1.0"/>
      <origin xyz="0 0 -0.1"/>
      <inertia ixx="0.003" ixy="0.0" ixz="0.0" iyy="0.003" iyz="0.0" izz="0.001"/>
    </inertial>
    <visual>
      <origin xyz="0 0 -0.1"/>
      <geometry>
        <cylinder length="0.2" radius="0.04"/>
      </geometry>
      <material name="green"/>
      <origin rpy="1.57075 0 0"/>
    </visual>
    <collision>
      <origin xyz="0 0 -0.1"/>
      <geometry>
        <cylinder length="0.2" radius="0.04"/>
      </geometry>
      <origin rpy="1.57075 0 0"/>
    </collision>
  </link>

  <joint name="right_hip_pitch_joint" type="revolute">
    <parent link="right_hip_yaw"/>
    <child link="right_hip_pitch"/>
    <origin xyz="0 0 -0.05"/>
    <axis xyz="0 1 0"/>
    <limit lower="-1.57" upper="0.3" effort="300" velocity="2"/>
    <dynamics damping="1.0" friction="0.1"/>
  </joint>

  <!-- Right Thigh -->
  <link name="right_thigh">
    <inertial>
      <mass value="2.0"/>
      <origin xyz="0 0 -0.2"/>
      <inertia ixx="0.04" ixy="0.0" ixz="0.0" iyy="0.04" iyz="0.0" izz="0.01"/>
    </inertial>
    <visual>
      <origin xyz="0 0 -0.2"/>
      <geometry>
        <cylinder length="0.4" radius="0.05"/>
      </geometry>
      <material name="green"/>
      <origin rpy="1.57075 0 0"/>
    </visual>
    <collision>
      <origin xyz="0 0 -0.2"/>
      <geometry>
        <cylinder length="0.4" radius="0.05"/>
      </geometry>
      <origin rpy="1.57075 0 0"/>
    </collision>
  </link>

  <joint name="right_thigh_joint" type="revolute">
    <parent link="right_hip_pitch"/>
    <child link="right_thigh"/>
    <origin xyz="0 0 -0.1"/>
    <axis xyz="0 1 0"/>
    <limit lower="-0.2" upper="2.0" effort="300" velocity="2"/>
    <dynamics damping="1.0" friction="0.1"/>
  </joint>

  <!-- Right Shin -->
  <link name="right_shin">
    <inertial>
      <mass value="1.5"/>
      <origin xyz="0 0 -0.2"/>
      <inertia ixx="0.03" ixy="0.0" ixz="0.0" iyy="0.03" iyz="0.0" izz="0.008"/>
    </inertial>
    <visual>
      <origin xyz="0 0 -0.2"/>
      <geometry>
        <cylinder length="0.4" radius="0.04"/>
      </geometry>
      <material name="green"/>
      <origin rpy="1.57075 0 0"/>
    </visual>
    <collision>
      <origin xyz="0 0 -0.2"/>
      <geometry>
        <cylinder length="0.4" radius="0.04"/>
      </geometry>
      <origin rpy="1.57075 0 0"/>
    </collision>
  </link>

  <joint name="right_shin_joint" type="revolute">
    <parent link="right_thigh"/>
    <child link="right_shin"/>
    <origin xyz="0 0 -0.4"/>
    <axis xyz="0 1 0"/>
    <limit lower="-2.0" upper="0.5" effort="250" velocity="2"/>
    <dynamics damping="1.0" friction="0.1"/>
  </joint>

  <!-- Right Ankle -->
  <link name="right_ankle">
    <inertial>
      <mass value="0.8"/>
      <origin xyz="0 0 -0.03"/>
      <inertia ixx="0.001" ixy="0.0" ixz="0.0" iyy="0.001" iyz="0.0" izz="0.001"/>
    </inertial>
    <visual>
      <origin xyz="0 0 -0.03"/>
      <geometry>
        <box size="0.08 0.1 0.06"/>
      </geometry>
      <material name="black"/>
    </visual>
    <collision>
      <origin xyz="0 0 -0.03"/>
      <geometry>
        <box size="0.08 0.1 0.06"/>
      </geometry>
    </collision>
  </link>

  <joint name="right_ankle_joint" type="revolute">
    <parent link="right_shin"/>
    <child link="right_ankle"/>
    <origin xyz="0 0 -0.4"/>
    <axis xyz="0 1 0"/>
    <limit lower="-0.5" upper="0.5" effort="100" velocity="2"/>
    <dynamics damping="0.5" friction="0.1"/>
  </joint>

  <!-- Right Foot -->
  <link name="right_foot">
    <inertial>
      <mass value="0.8"/>
      <origin xyz="0.05 0 -0.05"/>
      <inertia ixx="0.002" ixy="0.0" ixz="0.0" iyy="0.003" iyz="0.0" izz="0.004"/>
    </inertial>
    <visual>
      <origin xyz="0.05 0 -0.05"/>
      <geometry>
        <box size="0.2 0.1 0.1"/>
      </geometry>
      <material name="black"/>
    </visual>
    <collision>
      <origin xyz="0.05 0 -0.05"/>
      <geometry>
        <box size="0.2 0.1 0.1"/>
      </geometry>
    </collision>
  </link>

  <joint name="right_foot_joint" type="fixed">
    <parent link="right_ankle"/>
    <child link="right_foot"/>
    <origin xyz="0.05 0 -0.08"/>
  </joint>

  <!-- Left Shoulder (3 DOF) -->
  <link name="left_shoulder_roll">
    <inertial>
      <mass value="0.5"/>
      <origin xyz="0 0 0"/>
      <inertia ixx="0.001" ixy="0.0" ixz="0.0" iyy="0.001" iyz="0.0" izz="0.001"/>
    </inertial>
    <visual>
      <origin xyz="0 0 0"/>
      <geometry>
        <cylinder length="0.08" radius="0.03"/>
      </geometry>
      <material name="yellow"/>
      <origin rpy="1.57075 0 0"/>
    </visual>
    <collision>
      <origin xyz="0 0 0"/>
      <geometry>
        <cylinder length="0.08" radius="0.03"/>
      </geometry>
      <origin rpy="1.57075 0 0"/>
    </collision>
  </link>

  <joint name="left_shoulder_roll_joint" type="revolute">
    <parent link="torso"/>
    <child link="left_shoulder_roll"/>
    <origin xyz="-0.12 0 0.15"/>
    <axis xyz="1 0 0"/>
    <limit lower="-0.5" upper="1.57" effort="100" velocity="2"/>
    <dynamics damping="0.5" friction="0.1"/>
  </joint>

  <link name="left_shoulder_yaw">
    <inertial>
      <mass value="0.5"/>
      <origin xyz="0 0 0"/>
      <inertia ixx="0.001" ixy="0.0" ixz="0.0" iyy="0.001" iyz="0.0" izz="0.001"/>
    </inertial>
    <visual>
      <origin xyz="0 0 0"/>
      <geometry>
        <cylinder length="0.08" radius="0.03"/>
      </geometry>
      <material name="yellow"/>
      <origin rpy="1.57075 0 0"/>
    </visual>
    <collision>
      <origin xyz="0 0 0"/>
      <geometry>
        <cylinder length="0.08" radius="0.03"/>
      </geometry>
      <origin rpy="1.57075 0 0"/>
    </collision>
  </link>

  <joint name="left_shoulder_yaw_joint" type="revolute">
    <parent link="left_shoulder_roll"/>
    <child link="left_shoulder_yaw"/>
    <origin xyz="0 0 0"/>
    <axis xyz="0 0 1"/>
    <limit lower="-1.0" upper="1.0" effort="100" velocity="2"/>
    <dynamics damping="0.5" friction="0.1"/>
  </joint>

  <link name="left_shoulder_pitch">
    <inertial>
      <mass value="0.8"/>
      <origin xyz="0 0 -0.15"/>
      <inertia ixx="0.006" ixy="0.0" ixz="0.0" iyy="0.006" iyz="0.0" izz="0.002"/>
    </inertial>
    <visual>
      <origin xyz="0 0 -0.15"/>
      <geometry>
        <cylinder length="0.3" radius="0.04"/>
      </geometry>
      <material name="yellow"/>
      <origin rpy="1.57075 0 0"/>
    </visual>
    <collision>
      <origin xyz="0 0 -0.15"/>
      <geometry>
        <cylinder length="0.3" radius="0.04"/>
      </geometry>
      <origin rpy="1.57075 0 0"/>
    </collision>
  </link>

  <joint name="left_shoulder_pitch_joint" type="revolute">
    <parent link="left_shoulder_yaw"/>
    <child link="left_shoulder_pitch"/>
    <origin xyz="0 0 0"/>
    <axis xyz="0 1 0"/>
    <limit lower="-1.57" upper="1.57" effort="150" velocity="2"/>
    <dynamics damping="0.5" friction="0.1"/>
  </joint>

  <!-- Left Upper Arm -->
  <link name="left_upper_arm">
    <inertial>
      <mass value="0.8"/>
      <origin xyz="0 0 -0.15"/>
      <inertia ixx="0.006" ixy="0.0" ixz="0.0" iyy="0.006" iyz="0.0" izz="0.002"/>
    </inertial>
    <visual>
      <origin xyz="0 0 -0.15"/>
      <geometry>
        <cylinder length="0.3" radius="0.04"/>
      </geometry>
      <material name="yellow"/>
      <origin rpy="1.57075 0 0"/>
    </visual>
    <collision>
      <origin xyz="0 0 -0.15"/>
      <geometry>
        <cylinder length="0.3" radius="0.04"/>
      </geometry>
      <origin rpy="1.57075 0 0"/>
    </collision>
  </link>

  <joint name="left_upper_arm_joint" type="revolute">
    <parent link="left_shoulder_pitch"/>
    <child link="left_upper_arm"/>
    <origin xyz="0 0 0"/>
    <axis xyz="0 1 0"/>
    <limit lower="-1.57" upper="1.57" effort="150" velocity="2"/>
    <dynamics damping="0.5" friction="0.1"/>
  </joint>

  <!-- Left Lower Arm -->
  <link name="left_lower_arm">
    <inertial>
      <mass value="0.6"/>
      <origin xyz="0 0 -0.15"/>
      <inertia ixx="0.004" ixy="0.0" ixz="0.0" iyy="0.004" iyz="0.0" izz="0.0015"/>
    </inertial>
    <visual>
      <origin xyz="0 0 -0.15"/>
      <geometry>
        <cylinder length="0.3" radius="0.03"/>
      </geometry>
      <material name="yellow"/>
      <origin rpy="1.57075 0 0"/>
    </visual>
    <collision>
      <origin xyz="0 0 -0.15"/>
      <geometry>
        <cylinder length="0.3" radius="0.03"/>
      </geometry>
      <origin rpy="1.57075 0 0"/>
    </collision>
  </link>

  <joint name="left_lower_arm_joint" type="revolute">
    <parent link="left_upper_arm"/>
    <child link="left_lower_arm"/>
    <origin xyz="0 0 -0.3"/>
    <axis xyz="1 0 0"/>
    <limit lower="-1.57" upper="1.57" effort="100" velocity="2"/>
    <dynamics damping="0.5" friction="0.1"/>
  </joint>

  <!-- Right Shoulder (3 DOF) -->
  <link name="right_shoulder_roll">
    <inertial>
      <mass value="0.5"/>
      <origin xyz="0 0 0"/>
      <inertia ixx="0.001" ixy="0.0" ixz="0.0" iyy="0.001" iyz="0.0" izz="0.001"/>
    </inertial>
    <visual>
      <origin xyz="0 0 0"/>
      <geometry>
        <cylinder length="0.08" radius="0.03"/>
      </geometry>
      <material name="yellow"/>
      <origin rpy="1.57075 0 0"/>
    </visual>
    <collision>
      <origin xyz="0 0 0"/>
      <geometry>
        <cylinder length="0.08" radius="0.03"/>
      </geometry>
      <origin rpy="1.57075 0 0"/>
    </collision>
  </link>

  <joint name="right_shoulder_roll_joint" type="revolute">
    <parent link="torso"/>
    <child link="right_shoulder_roll"/>
    <origin xyz="0.12 0 0.15"/>
    <axis xyz="1 0 0"/>
    <limit lower="-1.57" upper="0.5" effort="100" velocity="2"/>
    <dynamics damping="0.5" friction="0.1"/>
  </joint>

  <link name="right_shoulder_yaw">
    <inertial>
      <mass value="0.5"/>
      <origin xyz="0 0 0"/>
      <inertia ixx="0.001" ixy="0.0" ixz="0.0" iyy="0.001" iyz="0.0" izz="0.001"/>
    </inertial>
    <visual>
      <origin xyz="0 0 0"/>
      <geometry>
        <cylinder length="0.08" radius="0.03"/>
      </geometry>
      <material name="yellow"/>
      <origin rpy="1.57075 0 0"/>
    </visual>
    <collision>
      <origin xyz="0 0 0"/>
      <geometry>
        <cylinder length="0.08" radius="0.03"/>
      </geometry>
      <origin rpy="1.57075 0 0"/>
    </collision>
  </link>

  <joint name="right_shoulder_yaw_joint" type="revolute">
    <parent link="right_shoulder_roll"/>
    <child link="right_shoulder_yaw"/>
    <origin xyz="0 0 0"/>
    <axis xyz="0 0 1"/>
    <limit lower="-1.0" upper="1.0" effort="100" velocity="2"/>
    <dynamics damping="0.5" friction="0.1"/>
  </joint>

  <link name="right_shoulder_pitch">
    <inertial>
      <mass value="0.8"/>
      <origin xyz="0 0 -0.15"/>
      <inertia ixx="0.006" ixy="0.0" ixz="0.0" iyy="0.006" iyz="0.0" izz="0.002"/>
    </inertial>
    <visual>
      <origin xyz="0 0 -0.15"/>
      <geometry>
        <cylinder length="0.3" radius="0.04"/>
      </geometry>
      <material name="yellow"/>
      <origin rpy="1.57075 0 0"/>
    </visual>
    <collision>
      <origin xyz="0 0 -0.15"/>
      <geometry>
        <cylinder length="0.3" radius="0.04"/>
      </geometry>
      <origin rpy="1.57075 0 0"/>
    </collision>
  </link>

  <joint name="right_shoulder_pitch_joint" type="revolute">
    <parent link="right_shoulder_yaw"/>
    <child link="right_shoulder_pitch"/>
    <origin xyz="0 0 0"/>
    <axis xyz="0 1 0"/>
    <limit lower="-1.57" upper="1.57" effort="150" velocity="2"/>
    <dynamics damping="0.5" friction="0.1"/>
  </joint>

  <!-- Right Upper Arm -->
  <link name="right_upper_arm">
    <inertial>
      <mass value="0.8"/>
      <origin xyz="0 0 -0.15"/>
      <inertia ixx="0.006" ixy="0.0" ixz="0.0" iyy="0.006" iyz="0.0" izz="0.002"/>
    </inertial>
    <visual>
      <origin xyz="0 0 -0.15"/>
      <geometry>
        <cylinder length="0.3" radius="0.04"/>
      </geometry>
      <material name="yellow"/>
      <origin rpy="1.57075 0 0"/>
    </visual>
    <collision>
      <origin xyz="0 0 -0.15"/>
      <geometry>
        <cylinder length="0.3" radius="0.04"/>
      </geometry>
      <origin rpy="1.57075 0 0"/>
    </collision>
  </link>

  <joint name="right_upper_arm_joint" type="revolute">
    <parent link="right_shoulder_pitch"/>
    <child link="right_upper_arm"/>
    <origin xyz="0 0 0"/>
    <axis xyz="0 1 0"/>
    <limit lower="-1.57" upper="1.57" effort="150" velocity="2"/>
    <dynamics damping="0.5" friction="0.1"/>
  </joint>

  <!-- Right Lower Arm -->
  <link name="right_lower_arm">
    <inertial>
      <mass value="0.6"/>
      <origin xyz="0 0 -0.15"/>
      <inertia ixx="0.004" ixy="0.0" ixz="0.0" iyy="0.004" iyz="0.0" izz="0.0015"/>
    </inertial>
    <visual>
      <origin xyz="0 0 -0.15"/>
      <geometry>
        <cylinder length="0.3" radius="0.03"/>
      </geometry>
      <material name="yellow"/>
      <origin rpy="1.57075 0 0"/>
    </visual>
    <collision>
      <origin xyz="0 0 -0.15"/>
      <geometry>
        <cylinder length="0.3" radius="0.03"/>
      </geometry>
      <origin rpy="1.57075 0 0"/>
    </collision>
  </link>

  <joint name="right_lower_arm_joint" type="revolute">
    <parent link="right_upper_arm"/>
    <child link="right_lower_arm"/>
    <origin xyz="0 0 -0.3"/>
    <axis xyz="1 0 0"/>
    <limit lower="-1.57" upper="1.57" effort="100" velocity="2"/>
    <dynamics damping="0.5" friction="0.1"/>
  </joint>

</robot>